<?xml version="1.0"?>
<robot name="macroed" xmlns:xacro="http://ros.org/wiki/xacro">

  <xacro:property name="width" value="0.2" />
  <xacro:property name="leglen" value="0.6" />
  <xacro:property name="polelen" value="0.2" />
  <xacro:property name="bodylen" value="0.6" />
  <xacro:property name="baselen" value="0.4" />
  <xacro:property name="wheeldiam" value="0.07" />
  <xacro:property name="pi" value="3.1415" />
  <xacro:macro name="default_inertial" params="mass"> </xacro:macro>
  
<link name="gtc_map">
    <collision>
      <geometry>
        <cylinder radius="${width}" length="${bodylen}"/>
      </geometry>
    </collision>
    <xacro:default_inertial mass="10"/>
  </link>

  <xacro:macro name="wheel" params="prefix suffix reflect"> </xacro:macro>
  <xacro:macro name="leg" params="prefix reflect"> </xacro:macro>
  <xacro:leg prefix="right" reflect="-1" />
  <xacro:leg prefix="left" reflect="1" />


  <joint name="gripper_extension" type="prismatic">
    <parent link="gtc_map"/>
    <child link="gripper_pole"/>
    <limit effort="0" lower="0" upper="0" velocity="0.5"/>
    <origin rpy="0 0 0" xyz="${width-.01} 0 0.2"/>
  </joint>

  <joint name="kia_model" type="revolute">
      <origin xyz="0 0 0" rpy="0 0 0"/>
      <parent link="gtc_map"/>
      <child link="gripper_pole"/>
      <limit lower="-0.6" upper="0.6" effort="0" velocity="0"/>
    </joint>

  

  <link name="gripper_pole"> </link>

  <xacro:macro name="gripper" params="prefix reflect">
    <joint name="${prefix}_gripper_joint" type="revolute">
      <axis xyz="0 0 ${reflect}"/>
      <limit effort="1000.0" lower="0.0" upper="0" velocity="0"/>
      <origin rpy="0 0 0" xyz="0 0 0"/>
      <parent link="gripper_pole"/>
      <child link="${prefix}_gripper"/>
    </joint>
    <link name="${prefix}_gripper">
      <visual>
        <origin rpy="0 0 0" xyz="0 0 0"/>
        <geometry>
          <mesh filename="package://rviz_mesh/meshes/gtc_map/gtc_map.dae"/>
        </geometry>
      </visual>
      <collision>
        <geometry>
          <mesh filename="package://rviz_mesh/meshes/gtc_map/gtc_map.dae"/>
        </geometry>
        <origin rpy="0 0 0" xyz="0 0 0"/>
      </collision>
      <xacro:default_inertial mass="10000"/>
    </link>
<!--
    <joint name="${prefix}_tip_joint" type="fixed">
      <parent link="${prefix}_gripper"/>
      <child link="${prefix}_tip"/>
    </joint>
    <link name="${prefix}_tip">
      <visual>
        <origin rpy="0 0 0" xyz="0 0 0"/>
        <geometry>
          <mesh filename="package://rviz_mesh/meshes/vehicle/kia.dae"/>
        </geometry>
      </visual>
      <collision>
        <geometry>
          <mesh filename="package://rviz_mesh/meshes/vehicle/kia.dae"/>
        </geometry>
        <origin rpy="0 0 0" xyz="0 0 0"/>
      </collision>
      <xacro:default_inertial mass="1000"/>
    </link>
-->
  </xacro:macro>  

  <xacro:gripper prefix="left" reflect="1" />
  <xacro:gripper prefix="right" reflect="-1" />

</robot>
